Workbook
Name \0: #REF!
Name \A: #REF!
Name \b: #REF!
Name \c: #REF!
Name \d: #REF!
Name \e: #REF!
Name \f: #REF!
Name \g: #REF!
Name \h: #REF!
Name \i: #REF!
Name \j: #REF!
Name \k: #REF!
Name \L: #REF!
Name \M: #REF!
Name \n: #REF!
Name \p: #REF!
Name \q: #REF!
Name \r: #REF!
Name \s: #REF!
Name \t: #REF!
Name \v: #REF!
Name \w: #REF!
Name \x: #REF!
Name \z: #REF!
Name ___: #REF!
Name ______fat1: #REF!
Name _____b1: #REF!
Name _____REF1: #REF!
Name ____b1: #REF!
Name ____com1: #REF!
Name ____com10: #REF!
Name ____com11: #REF!
Name ____com12: #REF!
Name ____com2: #REF!
Name ____com3: #REF!
Name ____com4: #REF!
Name ____com5: #REF!
Name ____com6: #REF!
Name ____com7: #REF!
Name ____com8: #REF!
Name ____com9: #REF!
Name ____fat1: #REF!
Name ____niv1: #REF!
Name ____niv10: #REF!
Name ____niv11: #REF!
Name ____niv12: #REF!
Name ____niv2: #REF!
Name ____niv3: #REF!
Name ____niv4: #REF!
Name ____niv5: #REF!
Name ____niv6: #REF!
Name ____niv7: #REF!
Name ____niv8: #REF!
Name ____niv9: #REF!
Name ____pg1: #REF!
Name ____pg2: #REF!
Name ____pr1: #REF!
Name ____pr10: #REF!
Name ____pr11: #REF!
Name ____pr12: #REF!

Sheet Demand vs Supply forecast
C1: Wk1 | D1: Wk1 | E1: Wk1 | F1: Wk1 | G1: Wk1 | H1: Wk2 | I1: Wk2 | J1: Wk2 | K1: Wk2 | L1: Wk2 | M1: Wk2 | N1: Wk2 | O1: Wk3 | P1: Wk3 | Q1: Wk3 | R1: Wk3 | S1: Wk3 | T1: Wk3 | U1: Wk3 | V1: Wk4 | W1: Wk4 | X1: Wk4 | Y1: Wk4 | Z1: Wk4 | AA1: Wk4 | AB1: Wk4 | AC1: Wk5 | AD1: Wk5 | AE1: Wk5 | AF1: Wk5 | AG1: Wk5 | AH1: Wk5 | AI1: Wk5 | AJ1: Wk6 | AK1: Wk6 | AL1: Wk6 | AM1: Wk6 | AN1: Wk6 | AO1: Wk6 | AP1: Wk6 | AQ1: Wk7 | AR1: Wk7 | AS1: Wk7 | AT1: Wk7 | AU1: Wk7 | AV1: Wk7 | AW1: Wk7 | AX1: Wk8 | AY1: Wk8 | AZ1: Wk8 | BA1: Wk8 | BB1: Wk8 | BC1: Wk8 | BD1: Wk8 | BE1: Wk9 | BF1: Wk9 | BG1: Wk9 | BH1: Wk9 | BI1: Wk9 | BJ1: Wk9 | BK1: Wk9 | BL1: Wk10 | BM1: Wk10 | BN1: Wk10 | BO1: Wk10 | BP1: Wk10 | BQ1: Wk10 | BR1: Wk10 | BS1: Wk11 | BT1: Wk11 | BU1: Wk11 | BV1: Wk11 | BW1: Wk11 | BX1: Wk11 | BY1: Wk11 | BZ1: Wk12 | CA1: Wk12 | CB1: Wk12 | CC1: Wk12 | CD1: Wk12 | CE1: Wk12 | CF1: Wk12 | CG1: Wk13 | CH1: Wk13 | CI1: Wk13 | CJ1: Wk13 | CK1: Wk13 | CL1: Wk13 | CM1: Wk13 | CN1: Wk14 | CO1: Wk14 | CP1: Wk14 | CQ1: Wk14 | CR1: Wk14 | CS1: Wk14 | CT1: Wk14 | CU1: Wk15 | CV1: Wk15 | CW1: Wk15 | CX1: Wk15 | CY1: Wk15 | CZ1: Wk15 | DA1: Wk15 | DB1: Wk16 | DC1: Wk16 | DD1: Wk16 | DE1: Wk16 | DF1: Wk16 | DG1: Wk16 | DH1: Wk16 | DI1: Wk17 | DJ1: Wk17 | DK1: Wk17 | DL1: Wk17 | DM1: Wk17 | DN1: Wk17 | DO1: Wk17 | DP1: Wk18 | DQ1: Wk18 | DR1: Wk18 | DS1: Wk18 | DT1: Wk18 | DU1: Wk18 | DV1: Wk18 | DW1: Wk19 | DX1: Wk19 | DY1: Wk19 | DZ1: Wk19 | EA1: Wk19 | EB1: Wk19 | EC1: Wk19 | ED1: Wk20 | EE1: Wk20 | EF1: Wk20 | EG1: Wk20 | EH1: Wk20 | EI1: Wk20 | EJ1: Wk20 | EK1: Wk21 | EL1: Wk21 | EM1: Wk21 | EN1: Wk21 | EO1: Wk21 | EP1: Wk21 | EQ1: Wk21 | ER1: Wk22 | ES1: Wk22 | ET1: Wk22 | EU1: Wk22 | EV1: Wk22 | EW1: Wk22 | EX1: Wk22 | EY1: Wk23 | EZ1: Wk23 | FA1: Wk23 | FB1: Wk23 | FC1: Wk23 | FD1: Wk23 | FE1: Wk23 | FF1: Wk24 | FG1: Wk24 | FH1: Wk24 | FI1: Wk24 | FJ1: Wk24 | FK1: Wk24 | FL1: Wk24 | FM1: Wk25 | FN1: Wk25 | FO1: Wk25 | FP1: Wk25 | FQ1: Wk25 | FR1: Wk25 | FS1: Wk25 | FT1: Wk26 | FU1: Wk26 | FV1: Wk26 | FW1: Wk26 | FX1: Wk26 | FY1: Wk26 | FZ1: Wk26 | GA1: Wk27 | GB1: Wk27 | GC1: Wk27 | GD1: Wk27 | GE1: Wk27 | GF1: Wk27 | GG1: Wk27 | GH1: Wk28 | GI1: Wk28 | GJ1: Wk28 | GK1: Wk28 | GL1: Wk28 | GM1: Wk28 | GN1: Wk28 | GO1: Wk29 | GP1: Wk29 | GQ1: Wk29 | GR1: Wk29 | GS1: Wk29 | GT1: Wk29 | GU1: Wk29 | GV1: Wk30 | GW1: Wk30 | GX1: Wk30 | GY1: Wk30 | GZ1: Wk30 | HA1: Wk30 | HB1: Wk30 | HC1: Wk31 | HD1: Wk31 | HE1: Wk31 | HF1: Wk31 | HG1: Wk31 | HH1: Wk31 | HI1: Wk31 | HJ1: Wk32 | HK1: Wk32 | HL1: Wk32 | HM1: Wk32 | HN1: Wk32 | HO1: Wk32 | HP1: Wk32 | HQ1: Wk33 | HR1: Wk33 | HS1: Wk33 | HT1: Wk33 | HU1: Wk33 | HV1: Wk33 | HW1: Wk33 | HX1: Wk34 | HY1: Wk34 | HZ1: Wk34 | IA1: Wk34 | IB1: Wk34 | IC1: Wk34 | ID1: Wk34 | IE1: Wk35 | IF1: Wk35 | IG1: Wk35 | IH1: Wk35 | II1: Wk35 | IJ1: Wk35 | IK1: Wk35 | IL1: Wk36 | IM1: Wk36 | IN1: Wk36 | IO1: Wk36 | IP1: Wk36 | IQ1: Wk36 | IR1: Wk36 | IS1: Wk37 | IT1: Wk37 | IU1: Wk37 | IV1: Wk37 | IW1: Wk37 | IX1: Wk37 | IY1: Wk37 | IZ1: Wk38 | JA1: Wk38 | JB1: Wk38 | JC1: Wk38 | JD1: Wk38 | JE1: Wk38 | JF1: Wk38 | JG1: Wk39 | JH1: Wk39 | JI1: Wk39 | JJ1: Wk39 | JK1: Wk39 | JL1: Wk39 | JM1: Wk39 | JN1: Wk40 | JO1: Wk40 | JP1: Wk40 | JQ1: Wk40 | JR1: Wk40 | JS1: Wk40 | JT1: Wk40 | JU1: Wk41 | JV1: Wk41 | JW1: Wk41 | JX1: Wk41 | JY1: Wk41 | JZ1: Wk41 | KA1: Wk41 | KB1: Wk42 | KC1: Wk42 | KD1: Wk42 | KE1: Wk42 | KF1: Wk42 | KG1: Wk42 | KH1: Wk42 | KI1: Wk43 | KJ1: Wk43 | KK1: Wk43 | KL1: Wk43 | KM1: Wk43 | KN1: Wk43 | KO1: Wk43 | KP1: Wk44 | KQ1: Wk44 | KR1: Wk44 | KS1: Wk44 | KT1: Wk44 | KU1: Wk44 | KV1: Wk44 | KW1: Wk45 | KX1: Wk45 | KY1: Wk45 | KZ1: Wk45 | LA1: Wk45 | LB1: Wk45 | LC1: Wk45 | LD1: Wk46 | LE1: Wk46 | LF1: Wk46 | LG1: Wk46 | LH1: Wk46 | LI1: Wk46 | LJ1: Wk46 | LK1: Wk47 | LL1: Wk47 | LM1: Wk47 | LN1: Wk47 | LO1: Wk47 | LP1: Wk47 | LQ1: Wk47 | LR1: Wk48 | LS1: Wk48 | LT1: Wk48 | LU1: Wk48 | LV1: Wk48 | LW1: Wk48 | LX1: Wk48 | LY1: Wk49 | LZ1: Wk49 | MA1: Wk49 | MB1: Wk49 | MC1: Wk49 | MD1: Wk49 | ME1: Wk49 | MF1: Wk50 | MG1: Wk50 | MH1: Wk50 | MI1: Wk50 | MJ1: Wk50 | MK1: Wk50 | ML1: Wk50 | MM1: Wk51 | MN1: Wk51 | MO1: Wk51 | MP1: Wk51 | MQ1: Wk51 | MR1: Wk51 | MS1: Wk51 | MT1: Wk52 | MU1: Wk52 | MV1: Wk52 | MW1: Wk52 | MX1: Wk52 | MY1: Wk52 | MZ1: Wk52 | NA1: Wk53 | NB1: Wk53 | NC1: Wk53
A2: RY | B2: 45657 | C2: 45658 | D2: 45659 | E2: 45660 | F2: 45661 | G2: 45662 | H2: 45663 | I2: 45664 | J2: 45665 | K2: 45666 | L2: 45667 | M2: 45668 | N2: 45669 | O2: 45670 | P2: 45671 | Q2: 45672 | R2: 45673 | S2: 45674 | T2: 45675 | U2: 45676 | V2: 45677 | W2: 45678 | X2: 45679 | Y2: 45680 | Z2: 45681 | AA2: 45682 | AB2: 45683 | AC2: 45684 | AD2: 45685 | AE2: 45686 | AF2: 45687 | AG2: 45688 | AH2: 45689 | AI2: 45690 | AJ2: 45691 | AK2: 45692 | AL2: 45693 | AM2: 45694 | AN2: 45695 | AO2: 45696 | AP2: 45697 | AQ2: 45698 | AR2: 45699 | AS2: 45700 | AT2: 45701 | AU2: 45702 | AV2: 45703 | AW2: 45704 | AX2: 45705 | AY2: 45706 | AZ2: 45707 | BA2: 45708 | BB2: 45709 | BC2: 45710 | BD2: 45711 | BE2: 45712 | BF2: 45713 | BG2: 45714 | BH2: 45715 | BI2: 45716 | BJ2: 45717 | BK2: 45718 | BL2: 45719 | BM2: 45720 | BN2: 45721 | BO2: 45722 | BP2: 45723 | BQ2: 45724 | BR2: 45725 | BS2: 45726 | BT2: 45727 | BU2: 45728 | BV2: 45729 | BW2: 45730 | BX2: 45731 | BY2: 45732 | BZ2: 45733 | CA2: 45734 | CB2: 45735 | CC2: 45736 | CD2: 45737 | CE2: 45738 | CF2: 45739 | CG2: 45740 | CH2: 45741 | CI2: 45742 | CJ2: 45743 | CK2: 45744 | CL2: 45745 | CM2: 45746 | CN2: 45747 | CO2: 45748 | CP2: 45749 | CQ2: 45750 | CR2: 45751 | CS2: 45752 | CT2: 45753 | CU2: 45754 | CV2: 45755 | CW2: 45756 | CX2: 45757 | CY2: 45758 | CZ2: 45759 | DA2: 45760 | DB2: 45761 | DC2: 45762 | DD2: 45763 | DE2: 45764 | DF2: 45765 | DG2: 45766 | DH2: 45767 | DI2: 45768 | DJ2: 45769 | DK2: 45770 | DL2: 45771 | DM2: 45772 | DN2: 45773 | DO2: 45774 | DP2: 45775 | DQ2: 45776 | DR2: 45777 | DS2: 45778 | DT2: 45779 | DU2: 45780 | DV2: 45781 | DW2: 45782 | DX2: 45783 | DY2: 45784 | DZ2: 45785 | EA2: 45786 | EB2: 45787 | EC2: 45788 | ED2: 45789 | EE2: 45790 | EF2: 45791 | EG2: 45792 | EH2: 45793 | EI2: 45794 | EJ2: 45795 | EK2: 45796 | EL2: 45797 | EM2: 45798 | EN2: 45799 | EO2: 45800 | EP2: 45801 | EQ2: 45802 | ER2: 45803 | ES2: 45804 | ET2: 45805 | EU2: 45806 | EV2: 45807 | EW2: 45808 | EX2: 45809 | EY2: 45810 | EZ2: 45811 | FA2: 45812 | FB2: 45813 | FC2: 45814 | FD2: 45815 | FE2: 45816 | FF2: 45817 | FG2: 45818 | FH2: 45819 | FI2: 45820 | FJ2: 45821 | FK2: 45822 | FL2: 45823 | FM2: 45824 | FN2: 45825 | FO2: 45826 | FP2: 45827 | FQ2: 45828 | FR2: 45829 | FS2: 45830 | FT2: 45831 | FU2: 45832 | FV2: 45833 | FW2: 45834 | FX2: 45835 | FY2: 45836 | FZ2: 45837 | GA2: 45838 | GB2: 45839 | GC2: 45840 | GD2: 45841 | GE2: 45842 | GF2: 45843 | GG2: 45844 | GH2: 45845 | GI2: 45846 | GJ2: 45847 | GK2: 45848 | GL2: 45849 | GM2: 45850 | GN2: 45851 | GO2: 45852 | GP2: 45853 | GQ2: 45854 | GR2: 45855 | GS2: 45856 | GT2: 45857 | GU2: 45858 | GV2: 45859 | GW2: 45860 | GX2: 45861 | GY2: 45862 | GZ2: 45863 | HA2: 45864 | HB2: 45865 | HC2: 45866 | HD2: 45867 | HE2: 45868 | HF2: 45869 | HG2: 45870 | HH2: 45871 | HI2: 45872 | HJ2: 45873 | HK2: 45874 | HL2: 45875 | HM2: 45876 | HN2: 45877 | HO2: 45878 | HP2: 45879 | HQ2: 45880 | HR2: 45881 | HS2: 45882 | HT2: 45883 | HU2: 45884 | HV2: 45885 | HW2: 45886 | HX2: 45887 | HY2: 45888 | HZ2: 45889 | IA2: 45890 | IB2: 45891 | IC2: 45892 | ID2: 45893 | IE2: 45894 | IF2: 45895 | IG2: 45896 | IH2: 45897 | II2: 45898 | IJ2: 45899 | IK2: 45900 | IL2: 45901 | IM2: 45902 | IN2: 45903 | IO2: 45904 | IP2: 45905 | IQ2: 45906 | IR2: 45907 | IS2: 45908 | IT2: 45909 | IU2: 45910 | IV2: 45911 | IW2: 45912 | IX2: 45913 | IY2: 45914 | IZ2: 45915 | JA2: 45916 | JB2: 45917 | JC2: 45918 | JD2: 45919 | JE2: 45920 | JF2: 45921 | JG2: 45922 | JH2: 45923 | JI2: 45924 | JJ2: 45925 | JK2: 45926 | JL2: 45927 | JM2: 45928 | JN2: 45929 | JO2: 45930 | JP2: 45931 | JQ2: 45932 | JR2: 45933 | JS2: 45934 | JT2: 45935 | JU2: 45936 | JV2: 45937 | JW2: 45938 | JX2: 45939 | JY2: 45940 | JZ2: 45941 | KA2: 45942 | KB2: 45943 | KC2: 45944 | KD2: 45945 | KE2: 45946 | KF2: 45947 | KG2: 45948 | KH2: 45949 | KI2: 45950 | KJ2: 45951 | KK2: 45952 | KL2: 45953 | KM2: 45954 | KN2: 45955 | KO2: 45956 | KP2: 45957 | KQ2: 45958 | KR2: 45959 | KS2: 45960 | KT2: 45961 | KU2: 45962 | KV2: 45963 | KW2: 45964 | KX2: 45965 | KY2: 45966 | KZ2: 45967 | LA2: 45968 | LB2: 45969 | LC2: 45970 | LD2: 45971 | LE2: 45972 | LF2: 45973 | LG2: 45974 | LH2: 45975 | LI2: 45976 | LJ2: 45977 | LK2: 45978 | LL2: 45979 | LM2: 45980 | LN2: 45981 | LO2: 45982 | LP2: 45983 | LQ2: 45984 | LR2: 45985 | LS2: 45986 | LT2: 45987 | LU2: 45988 | LV2: 45989 | LW2: 45990 | LX2: 45991 | LY2: 45992 | LZ2: 45993 | MA2: 45994 | MB2: 45995 | MC2: 45996 | MD2: 45997 | ME2: 45998 | MF2: 45999 | MG2: 46000 | MH2: 46001 | MI2: 46002 | MJ2: 46003 | MK2: 46004 | ML2: 46005 | MM2: 46006 | MN2: 46007 | MO2: 46008 | MP2: 46009 | MQ2: 46010 | MR2: 46011 | MS2: 46012 | MT2: 46013 | MU2: 46014 | MV2: 46015 | MW2: 46016 | MX2: 46017 | MY2: 46018 | MZ2: 46019 | NA2: 46020 | NB2: 46021 | NC2: 46022
B3: W04 | C3: W01 | D3: W01 | E3: W01 | F3: W01 | G3: W01 | H3: W02 | I3: W02 | J3: W02 | K3: W02 | L3: W02 | M3: W02 | N3: W02 | O3: W03 | P3: W03 | Q3: W03 | R3: W03 | S3: W03 | T3: W03 | U3: W03 | V3: W04 | W3: W04 | X3: W04 | Y3: W04 | Z3: W04 | AA3: W04 | AB3: W04 | AC3: W04 | AD3: W04 | AE3: W04 | AF3: W04 | AG3: W04 | AH3: W04 | AI3: W04 | AJ3: W01 | AK3: W01 | AL3: W01 | AM3: W01 | AN3: W01 | AO3: W01 | AP3: W01 | AQ3: W02 | AR3: W02 | AS3: W02 | AT3: W02 | AU3: W02 | AV3: W02 | AW3: W02 | AX3: W03 | AY3: W03 | AZ3: W03 | BA3: W03 | BB3: W03 | BC3: W03 | BD3: W03 | BE3: W04 | BF3: W04 | BG3: W04 | BH3: W04 | BI3: W04 | BJ3: W04 | BK3: W04 | BL3: W01 | BM3: W01 | BN3: W01 | BO3: W01 | BP3: W01 | BQ3: W01 | BR3: W01 | BS3: W02 | BT3: W02 | BU3: W02 | BV3: W02 | BW3: W02 | BX3: W02 | BY3: W02 | BZ3: W03 | CA3: W03 | CB3: W03 | CC3: W03 | CD3: W03 | CE3: W03 | CF3: W03 | CG3: W04 | CH3: W04 | CI3: W04 | CJ3: W04 | CK3: W04 | CL3: W04 | CM3: W04 | CN3: W01 | CO3: W01 | CP3: W01 | CQ3: W01 | CR3: W01 | CS3: W01 | CT3: W01 | CU3: W02 | CV3: W02 | CW3: W02 | CX3: W02 | CY3: W02 | CZ3: W02 | DA3: W02 | DB3: W03 | DC3: W03 | DD3: W03 | DE3: W03 | DF3: W03 | DG3: W03 | DH3: W03 | DI3: W04 | DJ3: W04 | DK3: W04 | DL3: W04 | DM3: W04 | DN3: W04 | DO3: W04 | DP3: W04 | DQ3: W04 | DR3: W04 | DS3: W04 | DT3: W04 | DU3: W01 | DV3: W01 | DW3: W01 | DX3: W02 | DY3: W02 | DZ3: W02 | EA3: W02 | EB3: W02 | EC3: W02 | ED3: W02 | EE3: W03 | EF3: W03 | EG3: W03 | EH3: W03 | EI3: W03 | EJ3: W03 | EK3: W03 | EL3: W04 | EM3: W04 | EN3: W04 | EO3: W04 | EP3: W04 | EQ3: W04 | ER3: W04 | ES3: W04 | ET3: W04 | EU3: W04 | EV3: W04 | EW3: W04 | EX3: W01 | EY3: W01 | EZ3: W01 | FA3: W01 | FB3: W01 | FC3: W01 | FD3: W01 | FE3: W01 | FF3: W01 | FG3: W02 | FH3: W02 | FI3: W02 | FJ3: W02 | FK3: W02 | FL3: W02 | FM3: W02 | FN3: W03 | FO3: W03 | FP3: W03 | FQ3: W03 | FR3: W03 | FS3: W03 | FT3: W03 | FU3: W04 | FV3: W04 | FW3: W04 | FX3: W04 | FY3: W04 | FZ3: W04 | GA3: W04 | GB3: W01 | GC3: W01 | GD3: W01 | GE3: W01 | GF3: W01 | GG3: W01 | GH3: W01 | GI3: W02 | GJ3: W02 | GK3: W02 | GL3: W02 | GM3: W02 | GN3: W02 | GO3: W02 | GP3: W03 | GQ3: W03 | GR3: W03 | GS3: W03 | GT3: W03 | GU3: W03 | GV3: W03 | GW3: W04 | GX3: W04 | GY3: W04 | GZ3: W04 | HA3: W04 | HB3: W04 | HC3: W04 | HD3: W04 | HE3: W04 | HF3: W04 | HG3: W01 | HH3: W01 | HI3: W01 | HJ3: W01 | HK3: W02 | HL3: W02 | HM3: W02 | HN3: W02 | HO3: W02 | HP3: W02 | HQ3: W02 | HR3: W03 | HS3: W03 | HT3: W03 | HU3: W03 | HV3: W03 | HW3: W03 | HX3: W03 | HY3: W04 | HZ3: W04 | IA3: W04 | IB3: W04 | IC3: W04 | ID3: W04 | IE3: W04 | IF3: W04 | IG3: W04 | IH3: W04 | II3: W04 | IJ3: W04 | IK3: W04 | IL3: W01 | IM3: W01 | IN3: W01 | IO3: W01 | IP3: W01 | IQ3: W01 | IR3: W01 | IS3: W01 | IT3: W02 | IU3: W02 | IV3: W02 | IW3: W02 | IX3: W02 | IY3: W02 | IZ3: W02 | JA3: W03 | JB3: W03 | JC3: W03 | JD3: W03 | JE3: W03 | JF3: W03 | JG3: W03 | JH3: W04 | JI3: W04 | JJ3: W04 | JK3: W04 | JL3: W04 | JM3: W04 | JN3: W04 | JO3: W04 | JP3: W01 | JQ3: W01 | JR3: W01 | JS3: W01 | JT3: W01 | JU3: W01 | JV3: W02 | JW3: W02 | JX3: W02 | JY3: W02 | JZ3: W02 | KA3: W02 | KB3: W02 | KC3: W03 | KD3: W03 | KE3: W03 | KF3: W03 | KG3: W03 | KH3: W03 | KI3: W03 | KJ3: W04 | KK3: W04 | KL3: W04 | KM3: W04 | KN3: W04 | KO3: W04 | KP3: W04 | KQ3: W04 | KR3: W04 | KS3: =VLOOKUP(KS2,[1]Parameter!$AD:$AE,2,0) -> W04 | KT3: W04 | KU3: W01 | KV3: W01 | KW3: W01 | KX3: W01 | KY3: W01 | KZ3: W01 | LA3: W01 | LB3: W01 | LC3: W01 | LD3: W01 | LE3: W02 | LF3: W02 | LG3: W02 | LH3: W02 | LI3: W02 | LJ3: W02 | LK3: W02 | LL3: W03 | LM3: W03 | LN3: W03 | LO3: W03 | LP3: W03 | LQ3: W03 | LR3: W03 | LS3: W04 | LT3: W04 | LU3: W04 | LV3: W04 | LW3: W04 | LX3: W04 | LY3: W01 | LZ3: W01 | MA3: W01 | MB3: W01 | MC3: W01 | MD3: W01 | ME3: W01 | MF3: W01 | MG3: W02 | MH3: W02 | MI3: W02 | MJ3: W02 | MK3: W02 | ML3: W02 | MM3: W02 | MN3: W03 | MO3: W03 | MP3: W03 | MQ3: W03 | MR3: W03 | MS3: W03 | MT3: W03 | MU3: W04 | MV3: W04 | MW3: W04 | MX3: W04 | MY3: W04 | MZ3: W04 | NA3: =VLOOKUP(NA2,[1]Parameter!$AD:$AE,2,0) -> W04 | NB3: =VLOOKUP(NB2,[1]Parameter!$AD:$AE,2,0) -> W04 | NC3: =VLOOKUP(NC2,[1]Parameter!$AD:$AE,2,0) -> W04
A4: RY | B4: Tue | C4: Wed | D4: Thu | E4: Fri | F4: Sat | G4: Sun | H4: Mon | I4: Tue | J4: Wed | K4: Thu | L4: Fri | M4: Sat | N4: Sun | O4: Mon | P4: Tue | Q4: Wed | R4: Thu | S4: Fri | T4: Sat | U4: Sun | V4: Mon | W4: Tue | X4: Wed | Y4: Thu | Z4: Fri | AA4: Sat | AB4: Sun | AC4: Mon | AD4: Tue | AE4: Wed | AF4: Thu | AG4: Fri | AH4: Sat | AI4: Sun | AJ4: Mon | AK4: Tue | AL4: Wed | AM4: Thu | AN4: Fri | AO4: Sat | AP4: Sun | AQ4: Mon | AR4: Tue | AS4: Wed | AT4: Thu | AU4: Fri | AV4: Sat | AW4: Sun | AX4: Mon | AY4: Tue | AZ4: Wed | BA4: Thu | BB4: Fri | BC4: Sat | BD4: Sun | BE4: Mon | BF4: Tue | BG4: Wed | BH4: Thu | BI4: Fri | BJ4: Sat | BK4: Sun | BL4: Mon | BM4: Tue | BN4: Wed | BO4: Thu | BP4: Fri | BQ4: Sat | BR4: Sun | BS4: Mon | BT4: Tue | BU4: Wed | BV4: Thu | BW4: Fri | BX4: Sat | BY4: Sun | BZ4: Mon | CA4: Tue | CB4: Wed | CC4: Thu | CD4: Fri | CE4: Sat | CF4: Sun | CG4: Mon | CH4: Tue | CI4: Wed | CJ4: Thu | CK4: Fri | CL4: Sat | CM4: Sun | CN4: Mon | CO4: Tue | CP4: Wed | CQ4: Thu | CR4: Fri | CS4: Sat | CT4: Sun | CU4: Mon | CV4: Tue | CW4: Wed | CX4: Thu | CY4: Fri | CZ4: Sat | DA4: Sun | DB4: Mon | DC4: Tue | DD4: Wed | DE4: Thu | DF4: Fri | DG4: Sat | DH4: Sun | DI4: Mon | DJ4: Tue | DK4: Wed | DL4: Thu | DM4: Fri | DN4: Sat | DO4: Sun | DP4: Mon | DQ4: Tue | DR4: Wed | DS4: Thu | DT4: Fri | DU4: Sat | DV4: Sun | DW4: Mon | DX4: Tue | DY4: Wed | DZ4: Thu | EA4: Fri | EB4: Sat | EC4: Sun | ED4: Mon | EE4: Tue | EF4: Wed | EG4: Thu | EH4: Fri | EI4: Sat | EJ4: Sun | EK4: Mon | EL4: Tue | EM4: Wed | EN4: Thu | EO4: Fri | EP4: Sat | EQ4: Sun | ER4: Mon | ES4: Tue | ET4: Wed | EU4: Thu | EV4: Fri | EW4: Sat | EX4: Sun | EY4: Mon | EZ4: Tue | FA4: Wed | FB4: Thu | FC4: Fri | FD4: Sat | FE4: Sun | FF4: Mon | FG4: Tue | FH4: Wed | FI4: Thu | FJ4: Fri | FK4: Sat | FL4: Sun | FM4: Mon | FN4: Tue | FO4: Wed | FP4: Thu | FQ4: Fri | FR4: Sat | FS4: Sun | FT4: Mon | FU4: Tue | FV4: Wed | FW4: Thu | FX4: Fri | FY4: Sat | FZ4: Sun | GA4: Mon | GB4: Tue | GC4: Wed | GD4: Thu | GE4: Fri | GF4: Sat | GG4: Sun | GH4: Mon | GI4: Tue | GJ4: Wed | GK4: Thu | GL4: Fri | GM4: Sat | GN4: Sun | GO4: Mon | GP4: Tue | GQ4: Wed | GR4: Thu | GS4: Fri | GT4: Sat | GU4: Sun | GV4: Mon | GW4: Tue | GX4: Wed | GY4: Thu | GZ4: Fri | HA4: Sat | HB4: Sun | HC4: Mon | HD4: Tue | HE4: Wed | HF4: Thu | HG4: Fri | HH4: Sat | HI4: Sun | HJ4: Mon | HK4: Tue | HL4: Wed | HM4: Thu | HN4: Fri | HO4: Sat | HP4: Sun | HQ4: Mon | HR4: Tue | HS4: Wed | HT4: Thu | HU4: Fri | HV4: Sat | HW4: Sun | HX4: Mon | HY4: Tue | HZ4: Wed | IA4: Thu | IB4: Fri | IC4: Sat | ID4: Sun | IE4: Mon | IF4: Tue | IG4: Wed | IH4: Thu | II4: Fri | IJ4: Sat | IK4: Sun | IL4: Mon | IM4: Tue | IN4: Wed | IO4: Thu | IP4: Fri | IQ4: Sat | IR4: Sun | IS4: Mon | IT4: Tue | IU4: Wed | IV4: Thu | IW4: Fri | IX4: Sat | IY4: Sun | IZ4: Mon | JA4: Tue | JB4: Wed | JC4: Thu | JD4: Fri | JE4: Sat | JF4: Sun | JG4: Mon | JH4: Tue | JI4: Wed | JJ4: Thu | JK4: Fri | JL4: Sat | JM4: Sun | JN4: Mon | JO4: Tue | JP4: Wed | JQ4: Thu | JR4: Fri | JS4: Sat | JT4: Sun | JU4: Mon | JV4: Tue | JW4: Wed | JX4: Thu | JY4: Fri | JZ4: Sat | KA4: Sun | KB4: Mon | KC4: Tue | KD4: Wed | KE4: Thu | KF4: Fri | KG4: Sat | KH4: Sun | KI4: Mon | KJ4: Tue | KK4: Wed | KL4: Thu | KM4: Fri | KN4: Sat | KO4: Sun | KP4: Mon | KQ4: Tue | KR4: Wed | KS4: Thu | KT4: Fri | KU4: Sat | KV4: Sun | KW4: Mon | KX4: Tue | KY4: Wed | KZ4: Thu | LA4: Fri | LB4: Sat | LC4: Sun | LD4: Mon | LE4: Tue | LF4: Wed | LG4: Thu | LH4: Fri | LI4: Sat | LJ4: Sun | LK4: Mon | LL4: Tue | LM4: Wed | LN4: Thu | LO4: Fri | LP4: Sat | LQ4: Sun | LR4: Mon | LS4: Tue | LT4: Wed | LU4: Thu | LV4: Fri | LW4: Sat | LX4: Sun | LY4: Mon | LZ4: Tue | MA4: Wed | MB4: Thu | MC4: Fri | MD4: Sat | ME4: Sun | MF4: Mon | MG4: Tue | MH4: Wed | MI4: Thu | MJ4: Fri | MK4: Sat | ML4: Sun | MM4: Mon | MN4: Tue | MO4: Wed | MP4: Thu | MQ4: Fri | MR4: Sat | MS4: Sun | MT4: Mon | MU4: Tue | MV4: Wed | MW4: Thu | MX4: Fri | MY4: Sat | MZ4: Sun | NA4: Mon | NB4: Tue | NC4: Wed
A5: Inbound
A6: Productin plan | C6: 0 | D6: 124 | E6: 3509.5375 | F6: 3628.0625 | G6: 3111.275 | H6: 3402.5 | I6: 2197.1625 | J6: 2200.45 | K6: 1219.175 | L6: 906.6875 | M6: 1889.5375 | N6: 1473.925 | O6: 1486 | P6: 2161 | Q6: 2264 | R6: 2793 | S6: 2954 | T6: 2429 | U6: 1549 | V6: 1266 | W6: 1674 | X6: 1444 | Y6: 1784 | Z6: 2543 | AA6: 1724 | AB6: 2014 | AC6: 1553 | AD6: 2025 | AE6: 2264 | AF6: 2858 | AG6: 972 | AH6: 536 | AI6: 2726 | AJ6: 1189 | AK6: 1969 | AL6: 2517 | AM6: 2631 | AN6: 2352 | AO6: 2984 | AP6: 2826 | AQ6: 2375 | AR6: 2503 | AS6: 2129 | AT6: 2758 | AU6: 1864 | AV6: 1171 | AW6: 1066 | AX6: 2339 | AY6: 2499 | AZ6: 2287 | BA6: 1721 | BB6: 2320 | BC6: 3204 | BD6: 3064 | BE6: 2616 | BF6: 2485 | BG6: 2543 | BH6: 2904 | BI6: 3077 | BJ6: 3315 | BK6: 2975 | BL6: 2618 | BM6: 3110 | BN6: 3130 | BO6: 2982 | BP6: 2780 | BQ6: 2703 | BR6: 2068 | BS6: 2467 | BT6: 2943 | BU6: 2364 | BV6: 2732 | BW6: 2228 | BX6: 2529 | BY6: 1943 | BZ6: 2344 | CA6: 3980 | CB6: 3283 | CC6: 2618 | CD6: 2903 | CE6: 3133 | CF6: 3798 | CG6: 2884 | CH6: 2754 | CI6: 2575 | CJ6: 3402 | CK6: 1789 | CL6: 2965 | CM6: 2530 | CN6: 2044 | CO6: 2960 | CP6: 3098 | CQ6: 1725 | CR6: 2953 | CS6: 2340 | CT6: 2801 | CU6: 3269 | CV6: 3127 | CW6: 3261 | CX6: 3571 | CY6: 3512 | CZ6: 2707 | DA6: 2327 | DB6: 2023 | DC6: 3368 | DD6: 3231 | DE6: 2704 | DF6: 2893 | DG6: 2444 | DH6: 1644 | DI6: 1575 | DJ6: 1960 | DK6: 2625 | DL6: 2520 | DM6: 3245 | DN6: 3105 | DO6: 3193 | DP6: 2767 | DQ6: 2818 | DR6: 3752 | DS6: 959 | DT6: 656 | DU6: 3065 | DV6: 3182 | DW6: 2680 | DX6: 1486 | DY6: 2606 | DZ6: 2410 | EA6: 1834 | EB6: 2468 | EC6: 600 | ED6: 6 | EE6: 1832 | EF6: 2725 | EG6: 2745 | EH6: 2670 | EI6: 3084 | EJ6: 2068 | EK6: 3248 | EL6: 2108 | EM6: 1883 | EN6: 2333 | EO6: 1750 | EP6: 3143 | EQ6: 2802 | ER6: 2195 | ES6: 3130 | ET6: 2875 | EU6: 2171 | EV6: 1759 | EW6: 2362 | EX6: 1658 | EY6: 1837 | EZ6: 888 | FA6: 199 | FB6: 1601 | FC6: 2232 | FD6: 2821 | FE6: 2715 | FF6: 2208 | FG6: 2687 | FH6: 3571 | FI6: 2772 | FJ6: 2301 | FK6: 3376 | FL6: 3087 | FM6: 1438 | FN6: 1406 | FO6: 1655 | FP6: 1700 | FQ6: 3025 | FR6: 3792 | FS6: 2645 | FT6: 2326 | FU6: 2266 | FV6: 2552 | FW6: 3459 | FX6: 3105 | FY6: 3226 | FZ6: 1629 | GA6: 213 | GB6: 0 | GC6: 0 | GD6: 0 | GE6: 0 | GF6: 0 | GG6: 0 | GH6: 0 | GI6: 0 | GJ6: 0 | GK6: 0 | GL6: 0 | GM6: 0 | GN6: 0 | GO6: 0 | GP6: 0 | GQ6: 0 | GR6: 0 | GS6: 0 | GT6: 0 | GU6: 0 | GV6: 0 | GW6: 0 | GX6: 0 | GY6: 0 | GZ6: 0 | HA6: 0 | HB6: 0 | HC6: 0 | HD6: 0 | HE6: 0 | HF6: 0 | HG6: 2224 | HH6: 1712 | HI6: 2130 | HJ6: 2584 | HK6: 2429 | HL6: 1922 | HM6: 1439 | HN6: 1916 | HO6: 3058 | HP6: 2554 | HQ6: 1217 | HR6: 738 | HS6: 1592 | HT6: 2810 | HU6: 2859 | HV6: 2716 | HW6: 2635 | HX6: 2912 | HY6: 2898 | HZ6: 3046 | IA6: 2631 | IB6: 2668 | IC6: 3593 | ID6: 1375 | IE6: 1573 | IF6: 2752 | IG6: 2541 | IH6: 2730 | II6: 3411 | IJ6: 2691 | IK6: 728 | IL6: 2993 | IM6: 2702 | IN6: 2319 | IO6: 2229 | IP6: 2269 | IQ6: 1025 | IR6: 35 | IS6: 1363 | IT6: 3308 | IU6: 3412 | IV6: 2030 | IW6: 2268 | IX6: 818 | IY6: 708 | IZ6: 1344 | JA6: 1777 | JB6: 1353 | JC6: 2009 | JD6: 2773 | JE6: 2600 | JF6: 2255 | JG6: 2089 | JH6: 1838 | JI6: 896 | JJ6: 2254 | JK6: 3108 | JL6: 2533 | JM6: 2224 | JN6: 2445 | JO6: 2020 | JP6: 2435 | JQ6: 1749 | JR6: 1108 | JS6: 1067 | JT6: 2015 | JU6: 2930 | JV6: 2124 | JW6: 2906.5288 | JX6: 1904 | JY6: 2238 | JZ6: 2646 | KA6: 78 | KB6: 0 | KC6: 1365 | KD6: 3192 | KE6: 3593 | KF6: 1741 | KG6: 2537 | KH6: 3664 | KI6: 2840 | KJ6: 3090 | KK6: 2960 | KL6: 795 | KM6: 1193 | KN6: 2875 | KO6: 2626 | KP6: 1483 | KQ6: 2791 | KR6: 2842 | KS6: 2477 | KT6: 583 | KU6: 2831 | KV6: 2067 | KW6: 962 | KX6: 2280 | KY6: 3318 | KZ6: 1729 | LA6: 1134 | LB6: 2976 | LC6: 3413 | LD6: 2282 | LE6: 2728 | LF6: 3018 | LG6: 2995 | LH6: 2744.3323 | LI6: 248 | LJ6: 795 | LK6: 1168 | LL6: 2930 | LM6: 3030 | LN6: 2602 | LO6: 1666 | LP6: 2899 | LQ6: 1607 | LR6: 1110 | LS6: 1829 | LT6: 3114 | LU6: 2298 | LV6: 2343 | LW6: 2680 | LX6: 2265 | LY6: 1309 | LZ6: 1730 | MA6: 3300 | MB6: 2817 | MC6: 602 | MD6: 574 | ME6: 2564 | MF6: 2712 | MG6: 2546 | MH6: 2356 | MI6: 2233 | MJ6: 1465 | MK6: 1290 | ML6: 1341 | MM6: 1818 | MN6: 3562 | MO6: 3543 | MP6: 2092 | MQ6: 0 | MR6: 1659 | MS6: 2819 | MT6: 2780 | MU6: 3078 | MV6: 3740 | MW6: 2300 | MX6: 3130 | MY6: 3028 | MZ6: 3192 | NA6: =IF(TODAY()<=NA2,NA42,NA47) -> 0 | NB6: =IF(TODAY()<=NB2,NB42,NB47) -> 0 | NC6: =IF(TODAY()<=NC2,NC42,NC47) -> 0
A7: Shuttle SR > RY | C7: 0 | D7: 0 | E7: 214 | F7: 269 | G7: 402 | H7: 464 | I7: 423 | J7: 105 | K7: 37 | L7: 161 | M7: 285 | N7: 397 | O7: 86 | P7: 272 | Q7: 292 | R7: 110 | S7: 27 | T7: 219 | U7: 353 | V7: 80 | W7: 32 | X7: 111 | Y7: 78 | Z7: 169 | AA7: 340 | AB7: 231 | AC7: 241 | AD7: 282 | AE7: 108 | AF7: 219 | AG7: 121 | AH7: 384 | AI7: 382 | AJ7: 371 | AK7: 516 | AL7: 270 | AM7: 362 | AN7: 191 | AO7: 326 | AP7: 285 | AQ7: 136 | AR7: 203 | AS7: 148 | AT7: 174 | AU7: 187 | AV7: 138 | AW7: 78 | AX7: 130 | AY7: 232 | AZ7: 213 | BA7: 291 | BB7: 280 | BC7: 389 | BD7: 279 | BE7: 231 | BF7: 293 | BG7: 83 | BH7: 276 | BI7: 156 | BJ7: 290 | BK7: 388 | BL7: 178 | BM7: 218 | BN7: 216 | BO7: 353 | BP7: 419 | BQ7: 389 | BR7: 426 | BS7: 307 | BT7: 268 | BU7: 358 | BV7: 464 | BW7: 427 | BX7: 350 | BY7: 251 | BZ7: 343 | CA7: 191 | CB7: 238 | CC7: 439 | CD7: 382 | CE7: 442 | CF7: 430 | CG7: 389 | CH7: 338 | CI7: 441 | CJ7: 260 | CK7: 260 | CL7: 261 | CM7: 262 | CN7: 156 | CO7: 77 | CP7: 371 | CQ7: 489 | CR7: 377 | CS7: 378 | CT7: 452 | CU7: 364 | CV7: 509 | CW7: 292 | CX7: 96 | CY7: 372 | CZ7: 272 | DA7: 335 | DB7: 193 | DC7: 0 | DD7: 59 | DE7: 318 | DF7: 380 | DG7: 407 | DH7: 306 | DI7: 333 | DJ7: 336 | DK7: 416 | DL7: 393 | DM7: 441 | DN7: 268 | DO7: 144 | DP7: 205 | DQ7: 155 | DR7: 162 | DS7: 217 | DT7: 208 | DU7: 250 | DV7: 240 | DW7: 315 | DX7: 314 | DY7: 225 | DZ7: 88 | EA7: 261 | EB7: 321 | EC7: 0 | ED7: 70 | EE7: 191 | EF7: 216 | EG7: 313 | EH7: 0 | EI7: 312 | EJ7: 312 | EK7: 288 | EL7: 264 | EM7: 264 | EN7: 173 | EO7: 120 | EP7: 378 | EQ7: 239 | ER7: 247 | ES7: 264 | ET7: 240 | EU7: 337 | EV7: 168 | EW7: 263 | EX7: 288 | EY7: 236 | EZ7: 48 | FA7: 226 | FB7: 206 | FC7: 282 | FD7: 336 | FE7: 156 | FF7: 346 | FG7: 191 | FH7: 263 | FI7: 195 | FJ7: 85 | FK7: 279 | FL7: 123 | FM7: 201 | FN7: 142 | FO7: 135 | FP7: 378 | FQ7: 398 | FR7: 402 | FS7: 278 | FT7: 200 | FU7: 331 | FV7: 234 | FW7: 378 | FX7: 288 | FY7: 153 | FZ7: 431 | GA7: 226 | GB7: 354 | GC7: 159 | GD7: 380 | GE7: 356 | GF7: 332 | GG7: 358 | GH7: 373 | GI7: 384 | GJ7: 167 | GK7: 111 | GL7: 251 | GM7: 460 | GN7: 236 | GO7: 243 | GP7: 91 | GQ7: 198 | GR7: 202 | GS7: 277 | GT7: 232 | GU7: 226 | GV7: 96 | GW7: 151 | GX7: 58 | GY7: 151 | GZ7: 81 | HA7: 73 | HB7: 120 | HC7: 282 | HD7: 125 | HE7: 33 | HF7: 154 | HG7: 122 | HH7: 166 | HI7: 351 | HJ7: 291 | HK7: 182 | HL7: 202 | HM7: 163 | HN7: 177 | HO7: 241 | HP7: 435 | HQ7: 364 | HR7: 282 | HS7: 280 | HT7: 205 | HU7: 181 | HV7: 260 | HW7: 315 | HX7: 257 | HY7: 240 | HZ7: 135 | IA7: 478 | IB7: 291 | IC7: 181 | ID7: 365 | IE7: 288 | IF7: 168 | IG7: 160 | IH7: 294 | II7: 102 | IJ7: 206 | IK7: 174 | IL7: 263 | IM7: 157 | IN7: 29 | IO7: 242 | IP7: 260 | IQ7: 279 | IR7: 437 | IS7: 253 | IT7: 0 | IU7: 168 | IV7: 340 | IW7: 208 | IX7: 215 | IY7: 596 | IZ7: 519 | JA7: 104 | JB7: 130 | JC7: 156 | JD7: 212 | JE7: 390 | JF7: 390 | JG7: 156 | JH7: 155 | JI7: 78 | JJ7: 301 | JK7: 179 | JL7: 377 | JM7: 323 | JN7: 218 | JO7: 171 | JP7: 211 | JQ7: 78 | JR7: 103 | JS7: 598 | JT7: 312 | JU7: 94 | JV7: 261 | JW7: 600 | JX7: 311 | JY7: 180 | JZ7: 547 | KA7: 367 | KB7: 363 | KC7: 50 | KD7: 0 | KE7: 312 | KF7: 156 | KG7: 348 | KH7: 454 | KI7: 182 | KJ7: 129 | KK7: 106 | KL7: 598 | KM7: 415 | KN7: 233 | KO7: 359 | KP7: 289 | KQ7: 208 | KR7: 208 | KS7: 204 | KT7: 208 | KU7: 572 | KV7: 338 | KW7: 50 | KX7: 50 | KY7: 26 | KZ7: 168 | LA7: 235 | LB7: 549 | LC7: 263 | LD7: 52 | LE7: 133 | LF7: 187 | LG7: 192 | LH7: 128 | LI7: 3 | LJ7: 598 | LK7: 151 | LL7: 27 | LM7: 211 | LN7: 336 | LO7: 205 | LP7: 160 | LQ7: 205 | LR7: 0 | LS7: 23 | LT7: 75 | LU7: 79 | LV7: 208 | LW7: 311 | LX7: 257 | LY7: 78 | LZ7: 284 | MA7: 182 | MB7: 233 | MC7: 260 | MD7: 339 | ME7: 414 | MF7: 258 | MG7: 338 | MH7: 245 | MI7: 184 | MJ7: 177 | MK7: 317 | ML7: 249 | MM7: 282 | MN7: 235 | MO7: 105 | MP7: 184 | MQ7: 442 | MR7: 183 | MS7: 172 | MT7: 81 | MU7: 153 | MV7: 140 | MW7: 82 | MX7: 241 | MY7: 232 | MZ7: 100 | NA7: =IF(TODAY()<=NA2,NA60,NA64) -> 0 | NB7: =IF(TODAY()<=NB2,NB60,NB64) -> 0 | NC7: =IF(TODAY()<=NC2,NC60,NC64) -> 0
A8: Shuttle Toyo > RY | C8: 0 | D8: 0 | E8: 26 | F8: 0 | G8: 111 | H8: 104 | I8: 0 | J8: 102 | K8: 156 | L8: 180 | M8: 26 | N8: 75 | O8: 51 | P8: 104 | Q8: 51 | R8: 103 | S8: 24 | T8: 26 | U8: 26 | V8: 51 | W8: 0 | X8: 0 | Y8: 26 | Z8: 0 | AA8: 89 | AB8: 25 | AC8: 51 | AD8: 52 | AE8: 51 | AF8: 77 | AG8: 26 | AH8: 76 | AI8: 26 | AJ8: 0 | AK8: 103 | AL8: 25 | AM8: 76 | AN8: 104 | AO8: 26 | AP8: 26 | AQ8: 26 | AR8: 51 | AS8: 104 | AT8: 26 | AU8: 52 | AV8: 51 | AW8: 52 | AX8: 52 | AY8: 52 | AZ8: 75 | BA8: 76 | BB8: 76 | BC8: 76 | BD8: 76 | BE8: 26 | BF8: 77 | BG8: 78 | BH8: 26 | BI8: 78 | BJ8: 104 | BK8: 78 | BL8: 26 | BM8: 104 | BN8: 130 | BO8: 103 | BP8: 128 | BQ8: 77 | BR8: 103 | BS8: 0 | BT8: 155 | BU8: 77 | BV8: 52 | BW8: 78 | BX8: 0 | BY8: 26 | BZ8: 0 | CA8: 78 | CB8: 76 | CC8: 101 | CD8: 0 | CE8: 51 | CF8: 26 | CG8: 0 | CH8: 26 | CI8: 78 | CJ8: 76 | CK8: 76 | CL8: 104 | CM8: 25 | CN8: 0 | CO8: 25 | CP8: 26 | CQ8: 0 | CR8: 75 | CS8: 154 | CT8: 52 | CU8: 0 | CV8: 77 | CW8: 129 | CX8: 104 | CY8: 100 | CZ8: 129 | DA8: 0 | DB8: 0 | DC8: 0 | DD8: 0 | DE8: 0 | DF8: 103 | DG8: 50 | DH8: 25 | DI8: 0 | DJ8: 50 | DK8: 52 | DL8: 78 | DM8: 102 | DN8: 207 | DO8: 104 | DP8: 0 | DQ8: 78 | DR8: 102 | DS8: 102 | DT8: 193 | DU8: 39 | DV8: 156 | DW8: 77 | DX8: 76 | DY8: 102 | DZ8: 0 | EA8: 153 | EB8: 102 | EC8: 0 | ED8: 0 | EE8: 52 | EF8: 51 | EG8: 52 | EH8: 0 | EI8: 52 | EJ8: 0 | EK8: 25 | EL8: 51 | EM8: 51 | EN8: 77 | EO8: 206 | EP8: 129 | EQ8: 0 | ER8: 25 | ES8: 25 | ET8: 26 | EU8: 51 | EV8: 104 | EW8: 104 | EX8: 78 | EY8: 26 | EZ8: 128 | FA8: 0 | FB8: 52 | FC8: 78 | FD8: 130 | FE8: 78 | FF8: 52 | FG8: 0 | FH8: 102 | FI8: 77 | FJ8: 75 | FK8: 77 | FL8: 50 | FM8: 0 | FN8: 78 | FO8: 26 | FP8: 50 | FQ8: 25 | FR8: 127 | FS8: 77 | FT8: 0 | FU8: 78 | FV8: 104 | FW8: 75 | FX8: 0 | FY8: 104 | FZ8: 52 | GA8: 0 | GB8: 52 | GC8: 104 | GD8: 52 | GE8: 77 | GF8: 78 | GG8: 25 | GH8: 0 | GI8: 52 | GJ8: 26 | GK8: 26 | GL8: 51 | GM8: 26 | GN8: 0 | GO8: 0 | GP8: 99 | GQ8: 0 | GR8: 104 | GS8: 0 | GT8: 51 | GU8: 26 | GV8: 26 | GW8: 78 | GX8: 51 | GY8: 26 | GZ8: 25 | HA8: 26 | HB8: 26 | HC8: 26 | HD8: 77 | HE8: 52 | HF8: 26 | HG8: 25 | HH8: 103 | HI8: 0 | HJ8: 26 | HK8: 26 | HL8: 25 | HM8: 78 | HN8: 78 | HO8: 52 | HP8: 25 | HQ8: 50 | HR8: 51 | HS8: 0 | HT8: 155 | HU8: 181 | HV8: 0 | HW8: 26 | HX8: 26 | HY8: 76 | HZ8: 23 | IA8: 25 | IB8: 104 | IC8: 103 | ID8: 103 | IE8: 0 | IF8: 77 | IG8: 49 | IH8: 103 | II8: 103 | IJ8: 77 | IK8: 48 | IL8: 26 | IM8: 76 | IN8: 129 | IO8: 50 | IP8: 26 | IQ8: 77 | IR8: 0 | IS8: 0 | IT8: 0 | IU8: 26 | IV8: 0 | IW8: 78 | IX8: 26 | IY8: 60 | IZ8: 0 | JA8: 50 | JB8: 52 | JC8: 26 | JD8: 78 | JE8: 76 | JF8: 26 | JG8: 0 | JH8: 129 | JI8: 155 | JJ8: 104 | JK8: 104 | JL8: 0 | JM8: 26 | JN8: 0 | JO8: 26 | JP8: 77 | JQ8: 50 | JR8: 52 | JS8: 26 | JT8: 25 | JU8: 26 | JV8: 52 | JW8: 52 | JX8: 52 | JY8: 78 | JZ8: 0 | KA8: 0 | KB8: 26 | KC8: 51 | KD8: 51 | KE8: 151 | KF8: 75 | KG8: 0 | KH8: 0 | KI8: 0 | KJ8: 0 | KK8: 50 | KL8: 26 | KM8: 52 | KN8: 103 | KO8: 26 | KP8: 54 | KQ8: 25 | KR8: 49 | KS8: 78 | KT8: 77 | KU8: 52 | KV8: 77 | KW8: 103 | KX8: 129 | KY8: 78 | KZ8: 77 | LA8: 153 | LB8: 26 | LC8: 26 | LD8: 52 | LE8: 26 | LF8: 76 | LG8: 49 | LH8: 26 | LI8: 0 | LJ8: 0 | LK8: 26 | LL8: 25 | LM8: 0 | LN8: 52 | LO8: 76 | LP8: 0 | LQ8: 0 | LR8: 47 | LS8: 8 | LT8: 25 | LU8: 20 | LV8: 0 | LW8: 127 | LX8: 5 | LY8: 0 | LZ8: 26 | MA8: 52 | MB8: 36 | MC8: 93 | MD8: 26 | ME8: 52 | MF8: 0 | MG8: 25 | MH8: 50 | MI8: 0 | MJ8: 78 | MK8: 50 | ML8: 26 | MM8: 0 | MN8: 51 | MO8: 25 | MP8: 76 | MQ8: 51 | MR8: 74 | MS8: 0 | MT8: 26 | MU8: 103 | MV8: 25 | MW8: 75 | MX8: 0 | MY8: 0 | MZ8: 0 | NA8: =IF(TODAY()<=NA2,NA46,NA50) -> 0 | NB8: =IF(TODAY()<=NB2,NB46,NB50) -> 0 | NC8: =IF(TODAY()<=NC2,NC46,NC50) -> 0
A9: Outbound | C9: 0.11554841 | D9: 0.16699686 | E9: 0.15869772 | F9: 0.15397095 | G9: 0.20688579 | H9: 0.13433756 | I9: 0.16950359 | J9: 0.15924683 | K9: 0.15442657 | L9: 0.12613489 | M9: 0.12080794 | N9: 0.13554262 | O9: 0.13751757 | P9: 0.16182275 | Q9: 0.16259327 | R9: 0.16470207 | S9: 0.1271899 | T9: 0.10629123 | U9: 0.13988321 | V9: 0.18898297 | W9: 0.18415465 | X9: 0.18781113 | Y9: 0.14495537 | Z9: 0.12070804 | AA9: 0.085782003 | AB9: 0.08760584 | AC9: 0.18898297 | AD9: 0.18415465 | AE9: 0.18781113 | AF9: 0.14495537 | AG9: 0.12070804 | AH9: 0.085782003 | AI9: 0.08760584 | AJ9: 0.09556495 | AK9: 0.1023353 | AL9: 0.11554841 | AM9: 0.16699686 | AN9: 0.15869772 | AO9: 0.15397095 | AP9: 0.20688579 | AQ9: 0.13433756 | AR9: 0.16950359 | AS9: 0.15924683 | AT9: 0.15442657 | AU9: 0.12613489 | AV9: 0.12080794 | AW9: 0.13554262 | AX9: 0.13751757 | AY9: 0.16182275 | AZ9: 0.16259327 | BA9: 0.16470207 | BB9: 0.1271899 | BC9: 0.10629123 | BD9: 0.13988321 | BE9: 0.18898297 | BF9: 0.18415465 | BG9: 0.18781113 | BH9: 0.14495537 | BI9: 0.12070804 | BJ9: 0.087105529 | BK9: 0.080783354 | BL9: 0.084091037 | BM9: 0.11467266 | BN9: 0.14907558 | BO9: 0.14252318 | BP9: 0.17047485 | BQ9: 0.15584153 | BR9: 0.18332116 | BS9: 0.15523134 | BT9: 0.15627761 | BU9: 0.16953034 | BV9: 0.17096024 | BW9: 0.13243432 | BX9: 0.10252267 | BY9: 0.11304348 | BZ9: 0.15236002 | CA9: 0.15941498 | CB9: 0.14084144 | CC9: 0.13887419 | CD9: 0.13800589 | CE9: 0.11970369 | CF9: 0.15079979 | CG9: 0.178809 | CH9: 0.1855782 | CI9: 0.16871907 | CJ9: 0.15768187 | CK9: 0.14132297 | CL9: 0.087105529 | CM9: 0.080783354 | CN9: 0.084091037 | CO9: 0.11467266 | CP9: 0.14907558 | CQ9: 0.14252318 | CR9: 0.17047485 | CS9: 0.15584153 | CT9: 0.18332116 | CU9: 0.15523134 | CV9: 0.15627761 | CW9: 0.16953034 | CX9: 0.17096024 | CY9: 0.13243432 | CZ9: 0.10252267 | DA9: 0.11304348 | DB9: 0.15236002 | DC9: 0.15941498 | DD9: 0.14084144 | DE9: 0.13887419 | DF9: 0.13800589 | DG9: 0.11970369 | DH9: 0.15079979 | DI9: 0.178809 | DJ9: 0.1855782 | DK9: 0.16871907 | DL9: 0.15768187 | DM9: 0.14132297 | DN9: 0.087105529 | DO9: 0.080783354 | DP9: 0.178809 | DQ9: 0.1855782 | DR9: 0.16871907 | DS9: 0.15768187 | DT9: 0.14132297 | DU9: 0.15584153 | DV9: 0.18332116 | DW9: 0.084091037 | DX9: 0.15627761 | DY9: 0.16953034 | DZ9: 0.17096024 | EA9: 0.13243432 | EB9: 0.10252267 | EC9: 0.11304348 | ED9: 0.15523134 | EE9: 0.15941498 | EF9: 0.14084144 | EG9: 0.13887419 | EH9: 0.13800589 | EI9: 0.11970369 | EJ9: 0.15079979 | EK9: 0.15236002 | EL9: 0.1855782 | EM9: 0.16871907 | EN9: 0.15768187 | EO9: 0.14132297 | EP9: 0.087105529 | EQ9: 0.080783354 | ER9: 0.178809 | ES9: 0.1855782 | ET9: 0.16871907 | EU9: 0.15768187 | EV9: 0.14132297 | EW9: 0.087105529 | EX9: 0.20688579 | EY9: 0.09556495 | EZ9: 0.1023353 | FA9: 0.11554841 | FB9: 0.16699686 | FC9: 0.15869772 | FD9: 0.15397095 | FE9: 0.20688579 | FF9: 0.09556495 | FG9: 0.16950359 | FH9: 0.15924683 | FI9: 0.15442657 | FJ9: 0.12613489 | FK9: 0.12080794 | FL9: 0.13554262 | FM9: 0.13433756 | FN9: 0.16182275 | FO9: 0.16259327 | FP9: 0.16470207 | FQ9: 0.1271899 | FR9: 0.10629123 | FS9: 0.13988321 | FT9: 0.13751757 | FU9: 0.18415465 | FV9: 0.18781113 | FW9: 0.14495537 | FX9: 0.12070804 | FY9: 0.085782003 | FZ9: 0.08760584 | GA9: 0.18898297 | GB9: 0.1023353 | GC9: 0.11554841 | GD9: 0.16699686 | GE9: 0.15869772 | GF9: 0.15397095 | GG9: 0.20688579 | GH9: 0.09556495 | GI9: 0.16950359 | GJ9: 0.15924683 | GK9: 0.15442657 | GL9: 0.12613489 | GM9: 0.12080794 | GN9: 0.13554262 | GO9: 0.13433756 | GP9: 0.16182275 | GQ9: 0.16259327 | GR9: 0.16470207 | GS9: 0.1271899 | GT9: 0.10629123 | GU9: 0.13988321 | GV9: 0.13751757 | GW9: 0.18415465 | GX9: 0.18781113 | GY9: 0.14495537 | GZ9: 0.12070804 | HA9: 0.085782003 | HB9: 0.08760584 | HC9: 0.18898297 | HD9: 0.18415465 | HE9: 0.18781113 | HF9: 0.14495537 | HG9: 0.15869772 | HH9: 0.15397095 | HI9: 0.20688579 | HJ9: 0.09556495 | HK9: 0.16950359 | HL9: 0.15924683 | HM9: 0.15442657 | HN9: 0.12613489 | HO9: 0.12080794 | HP9: 0.13554262 | HQ9: 0.13433756 | HR9: 0.16182275 | HS9: 0.16259327 | HT9: 0.16470207 | HU9: 0.1271899 | HV9: 0.10629123 | HW9: 0.13988321 | HX9: 0.13751757 | HY9: 0.18415465 | HZ9: 0.18781113 | IA9: 0.14495537 | IB9: 0.12070804 | IC9: 0.085782003 | ID9: 0.08760584 | IE9: 0.18898297 | IF9: 0.18415465 | IG9: 0.18781113 | IH9: 0.14495537 | II9: 0.12070804 | IJ9: 0.085782003 | IK9: 0.08760584 | IL9: 0.09556495 | IM9: 0.1023353 | IN9: 0.11554841 | IO9: 0.16699686 | IP9: 0.15869772 | IQ9: 0.15397095 | IR9: 0.20688579 | IS9: 0.09556495 | IT9: 0.16950359 | IU9: 0.15924683 | IV9: 0.15442657 | IW9: 0.12613489 | IX9: 0.12080794 | IY9: 0.13554262 | IZ9: 0.13433756 | JA9: 0.16182275 | JB9: 0.16259327 | JC9: 0.16470207 | JD9: 0.1271899 | JE9: 0.10629123 | JF9: 0.13988321 | JG9: 0.13751757 | JH9: 0.18415465 | JI9: 0.18781113 | JJ9: 0.14495537 | JK9: 0.12070804 | JL9: 0.085782003 | JM9: 0.08760584 | JN9: 0.18898297 | JO9: 0.18415465 | JP9: 0.14907558 | JQ9: 0.14252318 | JR9: 0.17047485 | JS9: 0.15584153 | JT9: 0.18332116 | JU9: 0.084091037 | JV9: 0.15627761 | JW9: 0.16953034 | JX9: 0.17096024 | JY9: 0.13243432 | JZ9: 0.10252267 | KA9: 0.11304348 | KB9: 0.15523134 | KC9: 0.15941498 | KD9: 0.14084144 | KE9: 0.13887419 | KF9: 0.13800589 | KG9: 0.11970369 | KH9: 0.15079979 | KI9: 0.15236002 | KJ9: 0.1855782 | KK9: 0.16871907 | KL9: 0.15768187 | KM9: 0.14132297 | KN9: 0.087105529 | KO9: 0.080783354 | KP9: 0.178809 | KQ9: 0.1855782 | KR9: 0.16871907 | KS9: =_xlfn.XLOOKUP(KS3&KS4,'[1]2024 Daily ratio'!$M$87:$M$93,'[1]2024 Daily ratio'!$B$87:$B$93,0,0,1)+_xlfn.XLOOKUP(KS3&KS4,'[1]2024 Daily ratio'!$N$87:$N$93,'[1]2024 Daily ratio'!$C$87:$C$93,0,0,1)+_xlfn.XLOOKUP(KS3&KS4,'[1]2024 Daily ratio'!$O$87:$O$93,'[1]2024 Daily ratio'!$D$87:$D$93,0,0,1)+_xlfn.XLOOKUP(KS3&KS4,'[1]2024 Daily ratio'!$P$87:$P$93,'[1]2024 Daily ratio'!$E$87:$E$93,0,0,1) -> 0.15768187 | KT9: 0.14132297 | KU9: 0.15584153 | KV9: 0.18332116 | KW9: 0.084091037 | KX9: 0.11467266 | KY9: 0.14907558 | KZ9: 0.14252318 | LA9: 0.17047485 | LB9: 0.15584153 | LC9: 0.18332116 | LD9: 0.084091037 | LE9: 0.15627761 | LF9: 0.16953034 | LG9: 0.17096024 | LH9: 0.13243432 | LI9: 0.10252267 | LJ9: 0.11304348 | LK9: 0.15523134 | LL9: 0.15941498 | LM9: 0.14084144 | LN9: 0.13887419 | LO9: 0.13800589 | LP9: 0.11970369 | LQ9: 0.15079979 | LR9: 0.15236002 | LS9: 0.1855782 | LT9: 0.16871907 | LU9: 0.15768187 | LV9: 0.14132297 | LW9: 0.087105529 | LX9: 0.080783354 | LY9: 0.084091037 | LZ9: 0.11467266 | MA9: 0.14907558 | MB9: 0.14252318 | MC9: 0.17047485 | MD9: 0.15584153 | ME9: 0.18332116 | MF9: 0.08 | MG9: 0.16 | MH9: 0.17 | MI9: 0.17 | MJ9: 0.16 | MK9: 0.1 | ML9: 0.16 | MM9: 0.08 | MN9: 0.16 | MO9: 0.17 | MP9: 0.17 | MQ9: 0.16 | MR9: 0.1 | MS9: 0.16 | MT9: 0.08 | MU9: 0.16 | MV9: 0.17 | MW9: 0.17 | MX9: 0.16 | MY9: 0.1 | MZ9: 0.16 | NA9: 0.08 | NB9: 0.16 | NC9: 0.17
A10: Daily sales forecast | C10: 1966 | D10: 1165 | E10: 1346 | F10: 868 | G10: 1287 | H10: 1427 | I10: 1844 | J10: 2068 | K10: 1901 | L10: 1774 | M10: 1418 | N10: 1501 | O10: 1849 | P10: 1220 | Q10: 1498 | R10: 1101 | S10: 1569 | T10: 953 | U10: 1171 | V10: 1341 | W10: 1736 | X10: 1240 | Y10: 1429 | Z10: 1391 | AA10: 1126 | AB10: 1391 | AC10: 1449 | AD10: 2230 | AE10: 1820 | AF10: 1809 | AG10: 1644 | AH10: 1479 | AI10: 1323 | AJ10: 1552 | AK10: 1802 | AL10: 2326 | AM10: 1808 | AN10: 1673 | AO10: 1759 | AP10: 1104 | AQ10: 1112 | AR10: 2166 | AS10: 1546 | AT10: 1720 | AU10: 1480 | AV10: 1027 | AW10: 1314 | AX10: 1864 | AY10: 2130 | AZ10: 2159 | BA10: 2684 | BB10: 2196 | BC10: 1164 | BD10: 1420 | BE10: 2393 | BF10: 2401 | BG10: 2684 | BH10: 2497 | BI10: 1703 | BJ10: 1486 | BK10: 1754 | BL10: 2016 | BM10: 2819 | BN10: 2689 | BO10: 2168 | BP10: 1803 | BQ10: 1911 | BR10: 1900 | BS10: 2240 | BT10: 2102 | BU10: 2179 | BV10: 2570 | BW10: 2545 | BX10: 2078 | BY10: 2071 | BZ10: 2693 | CA10: 2393 | CB10: 2898 | CC10: 2607 | CD10: 2438 | CE10: 1966 | CF10: 1904 | CG10: 2682 | CH10: 2333 | CI10: 1859 | CJ10: 1850 | CK10: 2010 | CL10: 3474 | CM10: 2113 | CN10: 2535 | CO10: 2464 | CP10: 2155 | CQ10: 2082 | CR10: 2041 | CS10: 2576 | CT10: 2643 | CU10: 2706 | CV10: 2905 | CW10: 3019 | CX10: 3147 | CY10: 2480 | CZ10: 2117 | DA10: 1191 | DB10: 1551 | DC10: 2768 | DD10: 2682 | DE10: 2092 | DF10: 1975 | DG10: 1120 | DH10: 1150 | DI10: 1692 | DJ10: 1664 | DK10: 2085 | DL10: 2386 | DM10: 2631 | DN10: 2541 | DO10: 2452 | DP10: 2786 | DQ10: 2552 | DR10: 2209 | DS10: 1530 | DT10: 1565 | DU10: 1648 | DV10: 1214 | DW10: 1517 | DX10: 1945 | DY10: 1873 | DZ10: 2270 | EA10: 2305 | EB10: 3585 | EC10: 448 | ED10: 1071 | EE10: 1568 | EF10: 2340 | EG10: 1595 | EH10: 130 | EI10: 1240 | EJ10: 1997 | EK10: 2014 | EL10: 2289 | EM10: 2525 | EN10: 2507 | EO10: 2192 | EP10: 1805 | EQ10: 1631 | ER10: 1992 | ES10: 1892 | ET10: 1783 | EU10: 1814 | EV10: 1915 | EW10: 1503 | EX10: 1319 | EY10: 1618 | EZ10: 2035 | FA10: 1493 | FB10: 2099 | FC10: 1668 | FD10: 2394 | FE10: 2036 | FF10: 1695 | FG10: 1711 | FH10: 2161 | FI10: 2065 | FJ10: 2232 | FK10: 2362 | FL10: 1528 | FM10: 1885 | FN10: 2180 | FO10: 1670 | FP10: 2065 | FQ10: 2224 | FR10: 1590 | FS10: 2008 | FT10: 2613 | FU10: 2024 | FV10: 2212 | FW10: 2344 | FX10: 2413 | FY10: 1995 | FZ10: 2048 | GA10: 2225 | GB10: 1514 | GC10: 1403 | GD10: 1479 | GE10: 1469 | GF10: 1288 | GG10: 1471 | GH10: 1591 | GI10: 1665 | GJ10: 1349 | GK10: 1634 | GL10: 1211 | GM10: 1316 | GN10: 1460 | GO10: 1850 | GP10: 1737 | GQ10: 1480 | GR10: 1653 | GS10: 1683 | GT10: 1398 | GU10: 1632 | GV10: 1609 | GW10: 2154 | GX10: 2989 | GY10: 2376 | GZ10: 2376 | HA10: 1735 | HB10: 1250 | HC10: 1720 | HD10: 2015 | HE10: 2582 | HF10: 1957 | HG10: 1240 | HH10: 1142 | HI10: 1394 | HJ10: 1441 | HK10: 2136 | HL10: 1998 | HM10: 2502 | HN10: 1928 | HO10: 2048 | HP10: 1839 | HQ10: 1802 | HR10: 1457 | HS10: 1931 | HT10: 1697 | HU10: 1817 | HV10: 2467 | HW10: 1707 | HX10: 2098 | HY10: 1744 | HZ10: 1893 | IA10: 2255 | IB10: 2165 | IC10: 2120 | ID10: 2206 | IE10: 1837 | IF10: 1692 | IG10: 2233 | IH10: 2632 | II10: 2244 | IJ10: 2043 | IK10: 1190 | IL10: 1116 | IM10: 2211 | IN10: 2546 | IO10: 1830 | IP10: 1562 | IQ10: 1175 | IR10: 1475 | IS10: 1271 | IT10: 1812 | IU10: 1129 | IV10: 1199 | IW10: 1154 | IX10: 916 | IY10: 1167 | IZ10: 1475 | JA10: 1653 | JB10: 2064 | JC10: 1693 | JD10: 1312 | JE10: 1371 | JF10: 1214 | JG10: 1644 | JH10: 1581 | JI10: 1774 | JJ10: 2162 | JK10: 1820 | JL10: 1783 | JM10: 1568 | JN10: 1929 | JO10: 1162 | JP10: 1069 | JQ10: 1532 | JR10: 1638 | JS10: 1238 | JT10: 1339 | JU10: 1290 | JV10: 1335 | JW10: 1311.7249 | JX10: 1700 | JY10: 1626 | JZ10: 1257 | KA10: 1855 | KB10: 1912 | KC10: 1993 | KD10: 2094 | KE10: 1441 | KF10: 1833 | KG10: 1383 | KH10: 1084 | KI10: 2008 | KJ10: 1853 | KK10: 2052 | KL10: 1431 | KM10: 1522 | KN10: 1388 | KO10: 960 | KP10: 1666 | KQ10: 1971 | KR10: 1716 | KS10: 1864 | KT10: 996 | KU10: 1003 | KV10: 1209 | KW10: 1202 | KX10: 1677 | KY10: 1495 | KZ10: 1662 | LA10: 1883 | LB10: 1509 | LC10: 1783 | LD10: 1560 | LE10: 1939 | LF10: 1909 | LG10: 1790 | LH10: 2555 | LI10: 63.75 | LJ10: 821 | LK10: 1746 | LL10: 1255 | LM10: 1565 | LN10: 1536 | LO10: 1332 | LP10: 1152 | LQ10: 1002 | LR10: 1620 | LS10: 1467 | LT10: 1730 | LU10: 1878 | LV10: 1345 | LW10: 1705 | LX10: 727 | LY10: 1149 | LZ10: 1316 | MA10: 1508 | MB10: 1735 | MC10: 1642 | MD10: 1133 | ME10: 1392 | MF10: 1521 | MG10: 1634 | MH10: 2108 | MI10: 2146 | MJ10: 1958 | MK10: 1515 | ML10: 1654 | MM10: 2336 | MN10: 2203 | MO10: 2264 | MP10: 1669 | MQ10: 1379 | MR10: =IF(TODAY()<=MR2,MR43,MR48) -> 1753 | MS10: 1416 | MT10: 1962 | MU10: 1969 | MV10: 1928 | MW10: 2123 | MX10: 1660 | MY10: 1232 | MZ10: 854 | NA10: =IF(TODAY()<=NA2,NA43,NA48)+100 -> 100 | NB10: =IF(TODAY()<=NB2,NB43,NB48) -> 0 | NC10: =IF(TODAY()<=NC2,NC43,NC48) -> 0
A11: Shuttle RY > SR | C11: 0 | D11: 174 | E11: 656 | F11: 914 | G11: 869 | H11: 1205 | I11: 269 | J11: 26 | K11: 270 | L11: 959 | M11: 1023 | N11: 1037 | O11: 988 | P11: 457 | Q11: 524 | R11: 439 | S11: 454 | T11: 388 | U11: 944 | V11: 518 | W11: 345 | X11: 127 | Y11: 211 | Z11: 220 | AA11: 878 | AB11: 495 | AC11: 850 | AD11: 488 | AE11: 415 | AF11: 475 | AG11: 503 | AH11: 1040 | AI11: 1322 | AJ11: 697 | AK11: 688 | AL11: 337 | AM11: 476 | AN11: 629 | AO11: 872 | AP11: 1236 | AQ11: 840 | AR11: 1110 | AS11: 901 | AT11: 851 | AU11: 449 | AV11: 207 | AW11: 259 | AX11: 162 | AY11: 546 | AZ11: 971 | BA11: 1028 | BB11: 817 | BC11: 682 | BD11: 1181 | BE11: 807 | BF11: 1116 | BG11: 1142 | BH11: 939 | BI11: 733 | BJ11: 1098 | BK11: 942 | BL11: 897 | BM11: 1019 | BN11: 1139 | BO11: 773 | BP11: 488 | BQ11: 724 | BR11: 826 | BS11: 665 | BT11: 483 | BU11: 585 | BV11: 911 | BW11: 765 | BX11: 828 | BY11: 1028 | BZ11: 794 | CA11: 666 | CB11: 664 | CC11: 805 | CD11: 601 | CE11: 963 | CF11: 1444 | CG11: 894 | CH11: 936 | CI11: 989 | CJ11: 700 | CK11: 784 | CL11: 785 | CM11: 786 | CN11: 156 | CO11: 358 | CP11: 617 | CQ11: 683 | CR11: 877 | CS11: 984 | CT11: 681 | CU11: 783 | CV11: 897 | CW11: 548 | CX11: 508 | CY11: 681 | CZ11: 703 | DA11: 1081 | DB11: 1321 | DC11: 864 | DD11: 838 | DE11: 695 | DF11: 1122 | DG11: 721 | DH11: 616 | DI11: 715 | DJ11: 490 | DK11: 828 | DL11: 805 | DM11: 766 | DN11: 1077 | DO11: 817 | DP11: 613 | DQ11: 715 | DR11: 952 | DS11: 889 | DT11: 851 | DU11: 834 | DV11: 574 | DW11: 654 | DX11: 495 | DY11: 531 | DZ11: 538 | EA11: 932 | EB11: 690 | EC11: 0 | ED11: 13 | EE11: 154 | EF11: 547 | EG11: 594 | EH11: 554 | EI11: 0 | EJ11: 745 | EK11: 718 | EL11: 387 | EM11: 515 | EN11: 521 | EO11: 727 | EP11: 740 | EQ11: 697 | ER11: 783 | ES11: 460 | ET11: 676 | EU11: 623 | EV11: 549 | EW11: 791 | EX11: 732 | EY11: 253 | EZ11: 617 | FA11: 307 | FB11: 175 | FC11: 304 | FD11: 80 | FE11: 655 | FF11: 667 | FG11: 488 | FH11: 626 | FI11: 535 | FJ11: 830 | FK11: 958 | FL11: 1015 | FM11: 1032 | FN11: 345 | FO11: 744 | FP11: 665 | FQ11: 654 | FR11: 440 | FS11: 1038 | FT11: 444 | FU11: 486 | FV11: 801 | FW11: 418 | FX11: 538 | FY11: 768 | FZ11: 1328 | GA11: 569 | GB11: 310 | GC11: 293 | GD11: 155 | GE11: 339 | GF11: 467 | GG11: 547 | GH11: 742 | GI11: 405 | GJ11: 213 | GK11: 743 | GL11: 912 | GM11: 540 | GN11: 576 | GO11: 286 | GP11: 269 | GQ11: 759 | GR11: 680 | GS11: 790 | GT11: 739 | GU11: 345 | GV11: 506 | GW11: 540 | GX11: 439 | GY11: 806 | GZ11: 646 | HA11: 788 | HB11: 924 | HC11: 917 | HD11: 349 | HE11: 263 | HF11: 633 | HG11: 504 | HH11: 618 | HI11: 858 | HJ11: 931 | HK11: 433 | HL11: 840 | HM11: 644 | HN11: 613 | HO11: 1020 | HP11: 928 | HQ11: 1196 | HR11: 813 | HS11: 597 | HT11: 599 | HU11: 833 | HV11: 838 | HW11: 1102 | HX11: 787 | HY11: 413 | HZ11: 531 | IA11: 554 | IB11: 631 | IC11: 632 | ID11: 795 | IE11: 492 | IF11: 585 | IG11: 672 | IH11: 1061 | II11: 817 | IJ11: 1097 | IK11: 722 | IL11: 263 | IM11: 283 | IN11: 982 | IO11: 691 | IP11: 541 | IQ11: 532 | IR11: 670 | IS11: 128 | IT11: 79 | IU11: 476 | IV11: 623 | IW11: 1076 | IX11: 210 | IY11: 990 | IZ11: 180 | JA11: 169 | JB11: 376 | JC11: 612 | JD11: 804 | JE11: 769 | JF11: 988 | JG11: 503 | JH11: 174 | JI11: 215 | JJ11: 729 | JK11: 1098 | JL11: 663 | JM11: 1007 | JN11: 632 | JO11: 342 | JP11: 507 | JQ11: 456 | JR11: 459 | JS11: 226 | JT11: 827 | JU11: 255 | JV11: 316 | JW11: 760 | JX11: 907 | JY11: 520 | JZ11: 1406 | KA11: 685 | KB11: 820 | KC11: 161 | KD11: 99 | KE11: 558 | KF11: 990 | KG11: 609 | KH11: 1074 | KI11: 361 | KJ11: 293 | KK11: 981 | KL11: 903 | KM11: 699 | KN11: 867 | KO11: 814 | KP11: 677 | KQ11: 885 | KR11: 728 | KS11: 658 | KT11: 836 | KU11: 1040 | KV11: 1190 | KW11: 937 | KX11: 752 | KY11: 1174 | KZ11: 1351 | LA11: 1054 | LB11: 379 | LC11: 1172 | LD11: 784 | LE11: 721 | LF11: 1154 | LG11: 1219 | LH11: 138 | LI11: 78 | LJ11: 1401 | LK11: 899 | LL11: 399 | LM11: 825 | LN11: 1055 | LO11: 1057 | LP11: 456 | LQ11: 1216 | LR11: 498 | LS11: 199 | LT11: 673 | LU11: 790 | LV11: 1044 | LW11: 659 | LX11: 774 | LY11: 834 | LZ11: 1026 | MA11: 968 | MB11: 797 | MC11: 623 | MD11: 530 | ME11: 449 | MF11: 99 | MG11: 224 | MH11: 430 | MI11: 903 | MJ11: 1008 | MK11: 960 | ML11: 916 | MM11: 468 | MN11: 823 | MO11: 564 | MP11: 685 | MQ11: 420 | MR11: 205 | MS11: 596 | MT11: 830 | MU11: 891 | MV11: 1055 | MW11: 719 | MX11: 874 | MY11: 933 | MZ11: 624 | NA11: =IF(TODAY()<=NA2,NA45,NA49) -> 0 | NB11: =IF(TODAY()<=NB2,NB45,NB49) -> 0 | NC11: =IF(TODAY()<=NC2,NC45,NC49) -> 0
A13: Warehouse
A14: WH capacity (100% Capacity) | B14: 18057 | C14: 17945 | D14: 17945 | E14: 17945 | F14: 17945 | G14: 17945 | H14: 17945 | I14: 17945 | J14: 17945 | K14: 17945 | L14: 17945 | M14: 17945 | N14: 17945 | O14: 17945 | P14: 17945 | Q14: 17945 | R14: 17945 | S14: 17945 | T14: 17945 | U14: 17945 | V14: 17945 | W14: 17945 | X14: 17945 | Y14: 17945 | Z14: 17945 | AA14: 17945 | AB14: 17945 | AC14: 17945 | AD14: 17945 | AE14: 17945 | AF14: 17945 | AG14: 17945 | AH14: 17945 | AI14: 17945 | AJ14: 17945 | AK14: 17945 | AL14: 17945 | AM14: 17945 | AN14: 17945 | AO14: 17945 | AP14: 17945 | AQ14: 17945 | AR14: 17945 | AS14: 17945 | AT14: 17945 | AU14: 17945 | AV14: 17945 | AW14: 17945 | AX14: 17945 | AY14: 17945 | AZ14: 17945 | BA14: 17945 | BB14: 17945 | BC14: 17945 | BD14: 17945 | BE14: 17945 | BF14: 17945 | BG14: 17945 | BH14: 17945 | BI14: 17945 | BJ14: 18057 | BK14: 18057 | BL14: 18057 | BM14: 18057 | BN14: 18057 | BO14: 18057 | BP14: 18057 | BQ14: 18057 | BR14: 18057 | BS14: 18057 | BT14: 18057 | BU14: 18057 | BV14: 18057 | BW14: 18057 | BX14: 18057 | BY14: 18057 | BZ14: 18057 | CA14: 18057 | CB14: 18057 | CC14: 18057 | CD14: 18057 | CE14: 18057 | CF14: 18057 | CG14: 18057 | CH14: 18057 | CI14: 18057 | CJ14: 18057 | CK14: 18057 | CL14: 18057 | CM14: 18057 | CN14: 18057 | CO14: 18057 | CP14: 18057 | CQ14: 18057 | CR14: 18057 | CS14: 18057 | CT14: 18057 | CU14: 18057 | CV14: 18057 | CW14: 18057 | CX14: 18057 | CY14: 18057 | CZ14: 18057 | DA14: 18057 | DB14: 18057 | DC14: 18057 | DD14: 18057 | DE14: 18057 | DF14: 18057 | DG14: 18057 | DH14: 18057 | DI14: 18057 | DJ14: 18057 | DK14: 18057 | DL14: 18057 | DM14: 18057 | DN14: 18057 | DO14: 18057 | DP14: 18057 | DQ14: 18057 | DR14: 18057 | DS14: 18057 | DT14: 18057 | DU14: 18057 | DV14: 18057 | DW14: 18057 | DX14: 18057 | DY14: 18057 | DZ14: 18057 | EA14: 18057 | EB14: 18057 | EC14: 18057 | ED14: 18057 | EE14: 18057 | EF14: 18057 | EG14: 18057 | EH14: 18057 | EI14: 18057 | EJ14: 18057 | EK14: 18057 | EL14: 18057 | EM14: 18057 | EN14: 18057 | EO14: 18057 | EP14: 18057 | EQ14: 18057 | ER14: 18057 | ES14: 18057 | ET14: 18057 | EU14: 18057 | EV14: 18057 | EW14: 18057 | EX14: 18057 | EY14: 18057 | EZ14: 18057 | FA14: 18057 | FB14: 18057 | FC14: 18057 | FD14: 18057 | FE14: 18057 | FF14: 18057 | FG14: 18057 | FH14: 18057 | FI14: 18057 | FJ14: 18057 | FK14: 18057 | FL14: 18057 | FM14: 18057 | FN14: 18057 | FO14: 18057 | FP14: 18057 | FQ14: 18057 | FR14: 18057 | FS14: 18057 | FT14: 18057 | FU14: 18057 | FV14: 18057 | FW14: 18057 | FX14: 18057 | FY14: 18057 | FZ14: 18057 | GA14: 18057 | GB14: 18057 | GC14: 18057 | GD14: 18057 | GE14: 18057 | GF14: 18057 | GG14: 18057 | GH14: 18057 | GI14: 18057 | GJ14: 18057 | GK14: 18057 | GL14: 18057 | GM14: 18057 | GN14: 18057 | GO14: 18057 | GP14: 18057 | GQ14: 18057 | GR14: 18057 | GS14: 18057 | GT14: 18057 | GU14: 18057 | GV14: 18057 | GW14: 18057 | GX14: 18057 | GY14: 18057 | GZ14: 18057 | HA14: 18057 | HB14: 18057 | HC14: 18057 | HD14: 18057 | HE14: 18057 | HF14: 18057 | HG14: 18057 | HH14: 18057 | HI14: 18057 | HJ14: 18057 | HK14: 18057 | HL14: 18057 | HM14: 18057 | HN14: 18057 | HO14: 18057 | HP14: 18057 | HQ14: 18057 | HR14: 18057 | HS14: 18057 | HT14: 18057 | HU14: 18057 | HV14: 18057 | HW14: 18057 | HX14: 18057 | HY14: 18057 | HZ14: 18057 | IA14: 18057 | IB14: 18057 | IC14: 18057 | ID14: 18057 | IE14: 18057 | IF14: 18057 | IG14: 18057 | IH14: 18057 | II14: 18057 | IJ14: 18057 | IK14: 18057 | IL14: 18057 | IM14: 18057 | IN14: 18057 | IO14: 18057 | IP14: 18057 | IQ14: 18057 | IR14: 18057 | IS14: 18057 | IT14: 18057 | IU14: 18057 | IV14: 18057 | IW14: 18057 | IX14: 18057 | IY14: 18057 | IZ14: 17257 | JA14: 17257 | JB14: 17257 | JC14: 17257 | JD14: 17257 | JE14: 17257 | JF14: 17257 | JG14: 17257 | JH14: 17257 | JI14: 17257 | JJ14: 17257 | JK14: 17257 | JL14: 17257 | JM14: 17257 | JN14: 17257 | JO14: 17257 | JP14: 17257 | JQ14: 17257 | JR14: 17257 | JS14: 17657 | JT14: 17657 | JU14: 17657 | JV14: 17657 | JW14: 18057 | JX14: 18057 | JY14: 18057 | JZ14: 18057 | KA14: 18057 | KB14: 18057 | KC14: 18057 | KD14: 18057 | KE14: 18057 | KF14: 18057 | KG14: 18057 | KH14: 18057 | KI14: 18057 | KJ14: 18057 | KK14: 18057 | KL14: 18057 | KM14: 18057 | KN14: 18057 | KO14: 18057 | KP14: 18057 | KQ14: 18057 | KR14: 18057 | KS14: 18057 | KT14: 18057 | KU14: 18057 | KV14: 18057 | KW14: 18057 | KX14: 18057 | KY14: 18057 | KZ14: 18057 | LA14: 18057 | LB14: 18057 | LC14: 18057 | LD14: 18057 | LE14: 18057 | LF14: 18057 | LG14: 18057 | LH14: 18057 | LI14: 18057 | LJ14: 18057 | LK14: 18057 | LL14: 18057 | LM14: 18057 | LN14: 18057 | LO14: 18057 | LP14: 18057 | LQ14: 18057 | LR14: 18057 | LS14: 18057 | LT14: 18057 | LU14: 18057 | LV14: 18057 | LW14: 18057 | LX14: 18057 | LY14: 18057 | LZ14: 18057 | MA14: 18057 | MB14: 18057 | MC14: 22068 | MD14: 22068 | ME14: 22068 | MF14: 22068 | MG14: 22068 | MH14: 22068 | MI14: 22068 | MJ14: 22068 | MK14: 22068 | ML14: 22068 | MM14: 22068 | MN14: 22068 | MO14: 22068 | MP14: 22068 | MQ14: 22068 | MR14: 22068 | MS14: 22068 | MT14: 22068 | MU14: 22068 | MV14: 22068 | MW14: 22068 | MX14: 22068 | MY14: 22068 | MZ14: 22068 | NA14: 22068 | NB14: 22068 | NC14: 22068
A15: Begin Inventory | C15: 13237 | D15: 11492 | E15: 10827 | F15: 12832 | G15: 14467 | H15: 15669 | I15: 16663 | J15: 17210 | K15: 17436 | L15: 15879 | M15: 14349 | N15: 14048.212 | O15: 13390 | P15: 12783 | Q15: 13505 | R15: 14153 | S15: 15470 | T15: 16519 | U15: 17497 | V15: 17330 | W15: 16830 | X15: 16475 | Y15: 16610 | Z15: 16766 | AA15: 17484 | AB15: 17732 | AC15: 17816 | AD15: 17262 | AE15: 16822 | AF15: 17023 | AG15: 17429 | AH15: 16401 | AI15: 14593 | AJ15: 15142 | AK15: 14593 | AL15: 14682 | AM15: 14851 | AN15: 15313 | AO15: 15434 | AP15: 15951 | AQ15: 16699 | AR15: 17134 | AS15: 16694 | AT15: 16486 | AU15: 17025 | AV15: 17465 | AW15: 15541 | AX15: 16555 | AY15: 16905 | AZ15: 16507 | BA15: 15908 | BB15: 14523 | BC15: 14063 | BD15: 14063 | BE15: 16176 | BF15: 16224 | BG15: 15051 | BH15: 13906 | BI15: 13428 | BJ15: 14415 | BK15: 15774 | BL15: 15975 | BM15: 15907 | BN15: 15250 | BO15: 15205 | BP15: 15660 | BQ15: 16498 | BR15: 17240 | BS15: 16954 | BT15: 16890 | BU15: 17563 | BV15: 17320 | BW15: 17076 | BX15: 16365 | BY15: 16378 | BZ15: 15240 | CA15: 14463 | CB15: 15585 | CC15: 15497 | CD15: 15008 | CE15: 15252 | CF15: 15619 | CG15: 16991 | CH15: 16318 | CI15: 16321 | CJ15: 16405 | CK15: 17510 | CL15: 16787 | CM15: 17361 | CN15: 17285 | CO15: 16816 | CP15: 16771 | CQ15: 17522 | CR15: 16964 | CS15: 17168 | CT15: 16458 | CU15: 16168 | CV15: 16146 | CW15: 16155 | CX15: 16135 | CY15: 16346 | CZ15: 17067 | DA15: 17205 | DB15: 17286 | DC15: 16549 | DD15: 16162 | DE15: 16221 | DF15: 15951 | DG15: 16567 | DH15: 17558 | DI15: 17656 | DJ15: 17217 | DK15: 17247 | DL15: 17373 | DM15: 17202 | DN15: 16900 | DO15: 16834 | DP15: 17245 | DQ15: 16826 | DR15: 16118 | DS15: 17236 | DT15: 15845 | DU15: 14285 | DV15: 15523 | DW15: 16680 | DX15: 17822 | DY15: 17243 | DZ15: 17615 | EA15: 17112 | EB15: 16285 | EC15: 14914 | ED15: 15066 | EE15: 14020 | EF15: 14136 | EG15: 14119 | EH15: 14921 | EI15: 15514 | EJ15: 17147 | EK15: 16414 | EL15: 17316 | EM15: 17021 | EN15: 16068 | EO15: 15358 | EP15: 14594 | EQ15: 15578 | ER15: 16183 | ES15: 16181 | ET15: 16943 | EU15: 17786 | EV15: 17722 | EW15: 16696 | EX15: 17210 | EY15: 17295 | EZ15: 17406 | FA15: 15786 | FB15: 14587 | FC15: 14099 | FD15: 14834 | FE15: 15255 | FF15: 15218 | FG15: 15528 | FH15: 15982 | FI15: 16890 | FJ15: 17357 | FK15: 16758 | FL15: 16998 | FM15: 17109 | FN15: 16341 | FO15: 15154 | FP15: 14556 | FQ15: 14251 | FR15: 14584 | FS15: 16777 | FT15: 16769 | FU15: 16136 | FV15: 15669 | FW15: 15919 | FX15: 17151 | FY15: 17092 | FZ15: 17696 | GA15: 16529 | GB15: 14349 | GC15: 15704 | GD15: 17112 | GE15: 17240 | GF15: 16389 | GG15: 17020 | GH15: 17554 | GI15: 18283 | GJ15: 18530 | GK15: 17746 | GL15: 16137 | GM15: 16330 | GN15: 16599 | GO15: 18207 | GP15: 17621 | GQ15: 17408 | GR15: 16982 | GS15: 15848 | GT15: 14939 | GU15: 15866 | GV15: 15436 | GW15: 15233 | GX15: 15140 | GY15: 14583 | GZ15: 14077 | HA15: 14010 | HB15: 14924 | HC15: 16038 | HD15: 16851 | HE15: 17147 | HF15: 16738 | HG15: 16337 | HH15: 17011 | HI15: 17163 | HJ15: 17123 | HK15: 17817 | HL15: 17719 | HM15: 16741 | HN15: 14961 | HO15: 14268 | HP15: 14813 | HQ15: 14749 | HR15: 13830 | HS15: 12591 | HT15: 12164 | HU15: 12409 | HV15: 12940 | HW15: 12472 | HX15: 12599 | HY15: 13189 | HZ15: 13939 | IA15: 15205 | IB15: 15094 | IC15: 15098 | ID15: 16364 | IE15: 16777 | IF15: 15879 | IG15: 16645 | IH15: 16161 | II15: 15649 | IJ15: 14867 | IK15: 14283 | IL15: 14729 | IM15: 16568 | IN15: 16813 | IO15: 15660 | IP15: 15597 | IQ15: 15951 | IR15: 15638 | IS15: 14013 | IT15: 13894 | IU15: 15016 | IV15: 17143 | IW15: 17206 | IX15: 17328 | IY15: 16577 | IZ15: 15737 | JA15: 15782 | JB15: 15741 | JC15: 14470 | JD15: 14209 | JE15: 15010 | JF15: 16049 | JG15: 16126 | JH15: 16136 | JI15: 16445 | JJ15: 15276 | JK15: 14759 | JL15: 15034 | JM15: 15286 | JN15: 15103 | JO15: 15222 | JP15: 15035 | JQ15: 16006 | JR15: 15779 | JS15: 14603 | JT15: 14524 | JU15: 14772 | JV15: 16259 | JW15: 15962 | JX15: 17162 | JY15: 16701 | JZ15: 16855 | KA15: 17309 | KB15: 15027 | KC15: 12532 | KD15: 11688 | KE15: 12587 | KF15: 14527 | KG15: 13595 | KH15: 14733 | KI15: 15945 | KJ15: 16594 | KK15: 17335 | KL15: 17285 | KM15: 15755 | KN15: 15552 | KO15: 16254 | KP15: 17473 | KQ15: 16912 | KR15: 16713 | KS15: 17245 | KT15: 17154 | KU15: 15994 | KV15: 17287 | KW15: 17244 | KX15: 16232 | KY15: 16151 | KZ15: 16750 | LA15: 15319 | LB15: 13983 | LC15: 15671 | LD15: 15849 | LE15: 15858 | LF15: 15867 | LG15: 16035 | LH15: 15852 | LI15: 15652 | LJ15: 15709.59 | LK15: 14262.66 | LL15: 13288.146 | LM15: 14488.937 | LN15: 15090.235 | LO15: 15283.445 | LP15: 15565 | LQ15: 16302 | LR15: 15843.212 | LS15: 14907.859 | LT15: 14830.214 | LU15: 15590.414 | LV15: 15236.497 | LW15: 15007.173 | LX15: 15845 | LY15: 16421.036 | LZ15: 15406.232 | MA15: 15027.035 | MB15: 16040.033 | MC15: 19847.959 | MD15: 14723.678 | ME15: 17113.734 | MF15: 14084.46 | MG15: 16588.516 | MH15: 17365.309 | MI15: 17199.799 | MJ15: 16334.734 | MK15: 15015.067 | ML15: 15015.067 | MM15: 14068.35 | MN15: 12975.984 | MO15: 13905.047 | MP15: 14478.815 | MQ15: 14236.067 | MR15: 12159.468 | MS15: 11274.541 | MT15: 12086.644 | MU15: 12004.992 | MV15: 12483.868 | MW15: 13073.083 | MX15: 13108 | MY15: 15005 | MZ15: 14591.362 | NA15: =22068*73.56% -> 16233.221 | NB15: =SUMIFS('[1]Inv-SCP'!$V:$V,'[1]Inv-SCP'!$B:$B,'Demand vs Supply forecast'!NB$2,'[1]Inv-SCP'!$J:$J,7101) -> 0 | NC15: =SUMIFS('[1]Inv-SCP'!$V:$V,'[1]Inv-SCP'!$B:$B,'Demand vs Supply forecast'!NC$2,'[1]Inv-SCP'!$J:$J,7101) -> 0
